[2024-05-20T03:39:42.125+0000] {taskinstance.py:1956} INFO - Dependencies all met for dep_context=non-requeueable deps ti=<TaskInstance: temp_humi_dag_csv.fetch_data_from_csv scheduled__2024-05-18T00:00:00+00:00 [queued]>
[2024-05-20T03:39:42.137+0000] {taskinstance.py:1956} INFO - Dependencies all met for dep_context=requeueable deps ti=<TaskInstance: temp_humi_dag_csv.fetch_data_from_csv scheduled__2024-05-18T00:00:00+00:00 [queued]>
[2024-05-20T03:39:42.138+0000] {taskinstance.py:2170} INFO - Starting attempt 1 of 4
[2024-05-20T03:39:42.153+0000] {taskinstance.py:2191} INFO - Executing <Task(PythonOperator): fetch_data_from_csv> on 2024-05-18 00:00:00+00:00
[2024-05-20T03:39:42.160+0000] {standard_task_runner.py:60} INFO - Started process 1191 to run task
[2024-05-20T03:39:42.175+0000] {standard_task_runner.py:87} INFO - Running: ['***', 'tasks', 'run', 'temp_humi_dag_csv', 'fetch_data_from_csv', 'scheduled__2024-05-18T00:00:00+00:00', '--job-id', '672', '--raw', '--subdir', 'DAGS_FOLDER/ICTTemp_Humi_CSV.py', '--cfg-path', '/tmp/tmp_2ky85uj']
[2024-05-20T03:39:42.179+0000] {standard_task_runner.py:88} INFO - Job 672: Subtask fetch_data_from_csv
[2024-05-20T03:39:42.242+0000] {task_command.py:423} INFO - Running <TaskInstance: temp_humi_dag_csv.fetch_data_from_csv scheduled__2024-05-18T00:00:00+00:00 [running]> on host e3e2dc6bc2be
[2024-05-20T03:39:42.552+0000] {taskinstance.py:2480} INFO - Exporting env vars: AIRFLOW_CTX_DAG_OWNER='Group4' AIRFLOW_CTX_DAG_ID='temp_humi_dag_csv' AIRFLOW_CTX_TASK_ID='fetch_data_from_csv' AIRFLOW_CTX_EXECUTION_DATE='2024-05-18T00:00:00+00:00' AIRFLOW_CTX_TRY_NUMBER='1' AIRFLOW_CTX_DAG_RUN_ID='scheduled__2024-05-18T00:00:00+00:00'
[2024-05-20T03:39:42.570+0000] {taskinstance.py:2698} ERROR - Task failed with exception
Traceback (most recent call last):
  File "/home/airflow/.local/lib/python3.8/site-packages/airflow/models/taskinstance.py", line 433, in _execute_task
    result = execute_callable(context=context, **execute_callable_kwargs)
  File "/home/airflow/.local/lib/python3.8/site-packages/airflow/operators/python.py", line 199, in execute
    return_value = self.execute_callable()
  File "/home/airflow/.local/lib/python3.8/site-packages/airflow/operators/python.py", line 216, in execute_callable
    return self.python_callable(*self.op_args, **self.op_kwargs)
  File "/opt/airflow/dags/ICTTemp_Humi_CSV.py", line 18, in fetch_and_process_data
    data = pd.read_csv(csv_file_path)
  File "/home/airflow/.local/lib/python3.8/site-packages/pandas/io/parsers/readers.py", line 912, in read_csv
    return _read(filepath_or_buffer, kwds)
  File "/home/airflow/.local/lib/python3.8/site-packages/pandas/io/parsers/readers.py", line 577, in _read
    parser = TextFileReader(filepath_or_buffer, **kwds)
  File "/home/airflow/.local/lib/python3.8/site-packages/pandas/io/parsers/readers.py", line 1407, in __init__
    self._engine = self._make_engine(f, self.engine)
  File "/home/airflow/.local/lib/python3.8/site-packages/pandas/io/parsers/readers.py", line 1661, in _make_engine
    self.handles = get_handle(
  File "/home/airflow/.local/lib/python3.8/site-packages/pandas/io/common.py", line 859, in get_handle
    handle = open(
FileNotFoundError: [Errno 2] No such file or directory: '/Users/fern/Desktop/project_data_en/ICTTemp_Humi.csv'
[2024-05-20T03:39:42.600+0000] {taskinstance.py:1138} INFO - Marking task as UP_FOR_RETRY. dag_id=temp_humi_dag_csv, task_id=fetch_data_from_csv, execution_date=20240518T000000, start_date=20240520T033942, end_date=20240520T033942
[2024-05-20T03:39:42.613+0000] {standard_task_runner.py:107} ERROR - Failed to execute job 672 for task fetch_data_from_csv ([Errno 2] No such file or directory: '/Users/fern/Desktop/project_data_en/ICTTemp_Humi.csv'; 1191)
[2024-05-20T03:39:42.670+0000] {local_task_job_runner.py:234} INFO - Task exited with return code 1
[2024-05-20T03:39:42.736+0000] {taskinstance.py:3280} INFO - 0 downstream tasks scheduled from follow-on schedule check
