[2024-05-17T05:45:16.407+0000] {taskinstance.py:1956} INFO - Dependencies all met for dep_context=non-requeueable deps ti=<TaskInstance: temp_humi_dag.delete_data manual__2024-05-17T05:45:15.454632+00:00 [queued]>
[2024-05-17T05:45:16.412+0000] {taskinstance.py:1956} INFO - Dependencies all met for dep_context=requeueable deps ti=<TaskInstance: temp_humi_dag.delete_data manual__2024-05-17T05:45:15.454632+00:00 [queued]>
[2024-05-17T05:45:16.413+0000] {taskinstance.py:2170} INFO - Starting attempt 1 of 4
[2024-05-17T05:45:16.420+0000] {taskinstance.py:2191} INFO - Executing <Task(PythonOperator): delete_data> on 2024-05-17 05:45:15.454632+00:00
[2024-05-17T05:45:16.424+0000] {standard_task_runner.py:60} INFO - Started process 4764 to run task
[2024-05-17T05:45:16.428+0000] {standard_task_runner.py:87} INFO - Running: ['***', 'tasks', 'run', 'temp_humi_dag', 'delete_data', 'manual__2024-05-17T05:45:15.454632+00:00', '--job-id', '172', '--raw', '--subdir', 'DAGS_FOLDER/ICTTemp_Humi_DAG.py', '--cfg-path', '/tmp/tmpvntx2op6']
[2024-05-17T05:45:16.430+0000] {standard_task_runner.py:88} INFO - Job 172: Subtask delete_data
[2024-05-17T05:45:16.469+0000] {task_command.py:423} INFO - Running <TaskInstance: temp_humi_dag.delete_data manual__2024-05-17T05:45:15.454632+00:00 [running]> on host e3e2dc6bc2be
[2024-05-17T05:45:16.524+0000] {taskinstance.py:2480} INFO - Exporting env vars: AIRFLOW_CTX_DAG_OWNER='Group4' AIRFLOW_CTX_DAG_ID='temp_humi_dag' AIRFLOW_CTX_TASK_ID='delete_data' AIRFLOW_CTX_EXECUTION_DATE='2024-05-17T05:45:15.454632+00:00' AIRFLOW_CTX_TRY_NUMBER='1' AIRFLOW_CTX_DAG_RUN_ID='manual__2024-05-17T05:45:15.454632+00:00'
[2024-05-17T05:45:16.529+0000] {logging_mixin.py:188} INFO - JSON data deleted successfully.
[2024-05-17T05:45:16.535+0000] {base.py:83} INFO - Using connection ID 'postgres_conn' for task execution.
[2024-05-17T05:45:16.538+0000] {logging_mixin.py:188} INFO - Error: connection to server at "localhost" (127.0.0.1), port 5432 failed: Connection refused
	Is the server running on that host and accepting TCP/IP connections?
connection to server at "localhost" (::1), port 5432 failed: Cannot assign requested address
	Is the server running on that host and accepting TCP/IP connections?
[2024-05-17T05:45:16.538+0000] {python.py:201} INFO - Done. Returned value was: None
[2024-05-17T05:45:16.545+0000] {taskinstance.py:1138} INFO - Marking task as SUCCESS. dag_id=temp_humi_dag, task_id=delete_data, execution_date=20240517T054515, start_date=20240517T054516, end_date=20240517T054516
[2024-05-17T05:45:16.602+0000] {local_task_job_runner.py:234} INFO - Task exited with return code 0
[2024-05-17T05:45:16.620+0000] {taskinstance.py:3280} INFO - 1 downstream tasks scheduled from follow-on schedule check
