[2024-05-17T05:45:17.434+0000] {taskinstance.py:1956} INFO - Dependencies all met for dep_context=non-requeueable deps ti=<TaskInstance: temp_humi_dag.create_table_database manual__2024-05-17T05:45:15.454632+00:00 [queued]>
[2024-05-17T05:45:17.439+0000] {taskinstance.py:1956} INFO - Dependencies all met for dep_context=requeueable deps ti=<TaskInstance: temp_humi_dag.create_table_database manual__2024-05-17T05:45:15.454632+00:00 [queued]>
[2024-05-17T05:45:17.440+0000] {taskinstance.py:2170} INFO - Starting attempt 1 of 4
[2024-05-17T05:45:17.447+0000] {taskinstance.py:2191} INFO - Executing <Task(PythonOperator): create_table_database> on 2024-05-17 05:45:15.454632+00:00
[2024-05-17T05:45:17.451+0000] {standard_task_runner.py:60} INFO - Started process 4766 to run task
[2024-05-17T05:45:17.454+0000] {standard_task_runner.py:87} INFO - Running: ['***', 'tasks', 'run', 'temp_humi_dag', 'create_table_database', 'manual__2024-05-17T05:45:15.454632+00:00', '--job-id', '173', '--raw', '--subdir', 'DAGS_FOLDER/ICTTemp_Humi_DAG.py', '--cfg-path', '/tmp/tmp0e_bur9h']
[2024-05-17T05:45:17.456+0000] {standard_task_runner.py:88} INFO - Job 173: Subtask create_table_database
[2024-05-17T05:45:17.485+0000] {task_command.py:423} INFO - Running <TaskInstance: temp_humi_dag.create_table_database manual__2024-05-17T05:45:15.454632+00:00 [running]> on host e3e2dc6bc2be
[2024-05-17T05:45:17.530+0000] {taskinstance.py:2480} INFO - Exporting env vars: AIRFLOW_CTX_DAG_OWNER='Group4' AIRFLOW_CTX_DAG_ID='temp_humi_dag' AIRFLOW_CTX_TASK_ID='create_table_database' AIRFLOW_CTX_EXECUTION_DATE='2024-05-17T05:45:15.454632+00:00' AIRFLOW_CTX_TRY_NUMBER='1' AIRFLOW_CTX_DAG_RUN_ID='manual__2024-05-17T05:45:15.454632+00:00'
[2024-05-17T05:45:17.537+0000] {base.py:83} INFO - Using connection ID 'postgres_conn' for task execution.
[2024-05-17T05:45:17.539+0000] {logging_mixin.py:188} INFO - Error: connection to server at "localhost" (127.0.0.1), port 5432 failed: Connection refused
	Is the server running on that host and accepting TCP/IP connections?
connection to server at "localhost" (::1), port 5432 failed: Cannot assign requested address
	Is the server running on that host and accepting TCP/IP connections?
[2024-05-17T05:45:17.540+0000] {python.py:201} INFO - Done. Returned value was: None
[2024-05-17T05:45:17.547+0000] {taskinstance.py:1138} INFO - Marking task as SUCCESS. dag_id=temp_humi_dag, task_id=create_table_database, execution_date=20240517T054515, start_date=20240517T054517, end_date=20240517T054517
[2024-05-17T05:45:17.588+0000] {local_task_job_runner.py:234} INFO - Task exited with return code 0
[2024-05-17T05:45:17.615+0000] {taskinstance.py:3280} INFO - 1 downstream tasks scheduled from follow-on schedule check
